Workbook
Name Début_Projet: Planification!#REF!

Sheet Planification
A1: Estimation des tâches
A2: Numéro | B2: Nom de la tâche | C2: Début tôt | D2: Début tard | E2: Fin tôt | F2: Fin tard | G2: Durée | H2: Marge | I2: Dépendances | J2: Membres | K2: Temps optimiste | L2: Temps pessimiste | M2: Temps vraisemblable | N2: Temps estimé | O2: Temps réel
B3: Tâches avant planification
A4: 0 | B4: Document de projet, architecture, gestion des risques, méthodologie, planification | C4: 45196 | D4: =C4+H4 -> 45196 | E4: =C4+G4 -> 45217 | F4: 45217 | G4: 21 | H4: =F4-E4 -> 0 | J4: Equipe | K4: 80 | L4: 80 | M4: 80 | N4: =(K4+L4+4*M4) / 6 -> 80 | O4: =SUMIF(Pamela!$A$3:$A$115,Planification!A4,Pamela!$C$3:$C$115) + SUMIF(Florian!$A$3:$A$110,Planification!A4,Florian!$C$3:$C$110) + SUMIF(Christophe!$A$3:$A$114,Planification!A4,Christophe!$C$3:$C$114) + SUMIF(Faton!$A$3:$A$112,Planification!A4,Faton!$C$3:$C$112) -> 80
B5: Milestone 1
A6: 1 | B6: Correction de l'architecture | C6: 45220 | D6: =C6+H6 -> 45233 | E6: =C6+G6 -> 45225 | F6: 45238 | G6: 5 | H6: =F6-E6 -> 13 | I6: 0 | J6: Chris | K6: 4 | L6: 7 | M6: 5 | N6: =(K6+L6+4*M6) / 6 -> 5.1666667 | O6: =SUMIF(Pamela!$A$3:$A$115,Planification!A6,Pamela!$C$3:$C$115) + SUMIF(Florian!$A$3:$A$110,Planification!A6,Florian!$C$3:$C$110) + SUMIF(Christophe!$A$3:$A$114,Planification!A6,Christophe!$C$3:$C$114) + SUMIF(Faton!$A$3:$A$112,Planification!A6,Faton!$C$3:$C$112) -> 0.5
B7: Milestone 2
A8: 2 | B8: Processus métier au clair pour réaliser les maquettes | C8: 45236 | D8: =C8+H8 -> 45236 | E8: =C8+G8 -> 45236 | F8: 45236 | G8: 0 | H8: =F8-E8 -> 0 | J8: Equipe | K8: 1 | L8: 1 | M8: 1 | N8: =(K8+L8+4*M8) / 6 -> 1 | O8: =SUMIF(Pamela!$A$3:$A$115,Planification!A8,Pamela!$C$3:$C$115) + SUMIF(Florian!$A$3:$A$110,Planification!A8,Florian!$C$3:$C$110) + SUMIF(Christophe!$A$3:$A$114,Planification!A8,Christophe!$C$3:$C$114) + SUMIF(Faton!$A$3:$A$112,Planification!A8,Faton!$C$3:$C$112) -> 1
A9: 3 | B9: Conception des maquettes | C9: 45241 | D9: =C9+H9 -> 45276 | E9: =C9+G9 -> 45247 | F9: 45282 | G9: 6 | H9: =F9-E9 -> 35 | I9: 2 | J9: Chris, Florian | K9: 15 | L9: 35 | M9: 32 | N9: =(K9+L9+4*M9) / 6 -> 29.666667 | O9: =SUMIF(Pamela!$A$3:$A$115,Planification!A9,Pamela!$C$3:$C$115) + SUMIF(Florian!$A$3:$A$110,Planification!A9,Florian!$C$3:$C$110) + SUMIF(Christophe!$A$3:$A$114,Planification!A9,Christophe!$C$3:$C$114) + SUMIF(Faton!$A$3:$A$112,Planification!A9,Faton!$C$3:$C$112) -> 24
A10: 4 | B10: Révisions et ajustements des maquettes | C10: 45257 | D10: =C10+H10 -> 45293 | E10: =C10+G10 -> 45264 | F10: 45300 | G10: 7 | H10: =F10-E10 -> 36 | I10: 3 | J10: Chris, Florian | K10: 8 | L10: 20 | M10: 15 | N10: =(K10+L10+4*M10) / 6 -> 14.666667 | O10: =SUMIF(Pamela!$A$3:$A$115,Planification!A10,Pamela!$C$3:$C$115) + SUMIF(Florian!$A$3:$A$110,Planification!A10,Florian!$C$3:$C$110) + SUMIF(Christophe!$A$3:$A$114,Planification!A10,Christophe!$C$3:$C$114) + SUMIF(Faton!$A$3:$A$112,Planification!A10,Faton!$C$3:$C$112) -> 0
B11: Milestone 3
A12: 5 | B12: Plan d'assurance qualité | C12: 45224 | D12: =C12+H12 -> 45231 | E12: =C12+G12 -> 45231 | F12: 45238 | G12: 7 | H12: =F12-E12 -> 7 | I12: 0 | J12: Chris, Florian, Pamela | K12: 5 | L12: 12 | M12: 10 | N12: =(K12+L12+4*M12) / 6 -> 9.5 | O12: =SUMIF(Pamela!$A$3:$A$115,Planification!A12,Pamela!$C$3:$C$115) + SUMIF(Florian!$A$3:$A$110,Planification!A12,Florian!$C$3:$C$110) + SUMIF(Christophe!$A$3:$A$114,Planification!A12,Christophe!$C$3:$C$114) + SUMIF(Faton!$A$3:$A$112,Planification!A12,Faton!$C$3:$C$112) -> 9
A13: 6 | B13: Plan de communication | C13: 45224 | D13: =C13+H13 -> 45231 | E13: =C13+G13 -> 45231 | F13: 45238 | G13: 7 | H13: =F13-E13 -> 7 | I13: 0 | J13: Florian, Faton | K13: 12 | L13: 17 | M13: 14 | N13: =(K13+L13+4*M13) / 6 -> 14.166667 | O13: =SUMIF(Pamela!$A$3:$A$115,Planification!A13,Pamela!$C$3:$C$115) + SUMIF(Florian!$A$3:$A$110,Planification!A13,Florian!$C$3:$C$110) + SUMIF(Christophe!$A$3:$A$114,Planification!A13,Christophe!$C$3:$C$114) + SUMIF(Faton!$A$3:$A$112,Planification!A13,Faton!$C$3:$C$112) -> 14
B14: Milestone 4
A15: 7 | B15: Choix du langage de programmation back-end | C15: 45254 | D15: =C15+H15 -> 45292 | E15: =C15+G15 -> 45261 | F15: 45299 | G15: 7 | H15: =F15-E15 -> 38 | J15: Pamela | K15: 2 | L15: 5 | M15: 3 | N15: =(K15+L15+4*M15) / 6 -> 3.1666667 | O15: =SUMIF(Pamela!$A$3:$A$115,Planification!A15,Pamela!$C$3:$C$115) + SUMIF(Florian!$A$3:$A$110,Planification!A15,Florian!$C$3:$C$110) + SUMIF(Christophe!$A$3:$A$114,Planification!A15,Christophe!$C$3:$C$114) + SUMIF(Faton!$A$3:$A$112,Planification!A15,Faton!$C$3:$C$112) -> 0
A16: 8 | B16: Choix du langage de programmation front-end | C16: 45254 | D16: =C16+H16 -> 45292 | E16: =C16+G16 -> 45261 | F16: 45299 | G16: 7 | H16: =F16-E16 -> 38 | J16: Pamela | K16: 2 | L16: 5 | M16: 3 | N16: =(K16+L16+4*M16) / 6 -> 3.1666667 | O16: =SUMIF(Pamela!$A$3:$A$115,Planification!A16,Pamela!$C$3:$C$115) + SUMIF(Florian!$A$3:$A$110,Planification!A16,Florian!$C$3:$C$110) + SUMIF(Christophe!$A$3:$A$114,Planification!A16,Christophe!$C$3:$C$114) + SUMIF(Faton!$A$3:$A$112,Planification!A16,Faton!$C$3:$C$112) -> 2.5
A17: 9 | B17: Choix du système de gestion de base de données | C17: 45254 | D17: =C17+H17 -> 45292 | E17: =C17+G17 -> 45261 | F17: 45299 | G17: 7 | H17: =F17-E17 -> 38 | J17: Pamela | K17: 2 | L17: 5 | M17: 3 | N17: =(K17+L17+4*M17) / 6 -> 3.1666667 | O17: =SUMIF(Pamela!$A$3:$A$115,Planification!A17,Pamela!$C$3:$C$115) + SUMIF(Florian!$A$3:$A$110,Planification!A17,Florian!$C$3:$C$110) + SUMIF(Christophe!$A$3:$A$114,Planification!A17,Christophe!$C$3:$C$114) + SUMIF(Faton!$A$3:$A$112,Planification!A17,Faton!$C$3:$C$112) -> 7
A18: 10 | B18: Choix des outils de collaboration et de développement | C18: 45254 | D18: =C18+H18 -> 45292 | E18: =C18+G18 -> 45261 | F18: 45299 | G18: 7 | H18: =F18-E18 -> 38 | J18: Pamela | K18: 2 | L18: 5 | M18: 3 | N18: =(K18+L18+4*M18) / 6 -> 3.1666667 | O18: =SUMIF(Pamela!$A$3:$A$115,Planification!A18,Pamela!$C$3:$C$115) + SUMIF(Florian!$A$3:$A$110,Planification!A18,Florian!$C$3:$C$110) + SUMIF(Christophe!$A$3:$A$114,Planification!A18,Christophe!$C$3:$C$114) + SUMIF(Faton!$A$3:$A$112,Planification!A18,Faton!$C$3:$C$112) -> 2
B19: Milestone 5
A20: 11 | B20: Installation de la SGBD choisie | C20: 45292 | D20: =C20+H20 -> 45321 | E20: =C20+G20 -> 45293 | F20: 45322 | G20: 1 | H20: =F20-E20 -> 29 | I20: 9 | J20: Florian | K20: 2 | L20: 8 | M20: 4 | N20: =(K20+L20+4*M20) / 6 -> 4.3333333 | O20: =SUMIF(Pamela!$A$3:$A$115,Planification!A20,Pamela!$C$3:$C$115) + SUMIF(Florian!$A$3:$A$110,Planification!A20,Florian!$C$3:$C$110) + SUMIF(Christophe!$A$3:$A$114,Planification!A20,Christophe!$C$3:$C$114) + SUMIF(Faton!$A$3:$A$112,Planification!A20,Faton!$C$3:$C$112) -> 0
A21: 12 | B21: Création des tables de la BDD | C21: 45293 | D21: =C21+H21 -> 45327 | E21: =C21+G21 -> 45299 | F21: 45333 | G21: 6 | H21: =F21-E21 -> 34 | I21: 11 | J21: Chris, Faton | K21: 8 | L21: 15 | M21: 12 | N21: =(K21+L21+4*M21) / 6 -> 11.833333 | O21: =SUMIF(Pamela!$A$3:$A$115,Planification!A21,Pamela!$C$3:$C$115) + SUMIF(Florian!$A$3:$A$110,Planification!A21,Florian!$C$3:$C$110) + SUMIF(Christophe!$A$3:$A$114,Planification!A21,Christophe!$C$3:$C$114) + SUMIF(Faton!$A$3:$A$112,Planification!A21,Faton!$C$3:$C$112) -> 0
A22: 13 | B22: Création des relations entre les tables et des contraintes | C22: 45300 | D22: =C22+H22 -> 45334 | E22: =C22+G22 -> 45306 | F22: 45340 | G22: 6 | H22: =F22-E22 -> 34 | I22: 12 | J22: Florian, Pamela | K22: 6 | L22: 15 | M22: 12 | N22: =(K22+L22+4*M22) / 6 -> 11.5 | O22: =SUMIF(Pamela!$A$3:$A$115,Planification!A22,Pamela!$C$3:$C$115) + SUMIF(Florian!$A$3:$A$110,Planification!A22,Florian!$C$3:$C$110) + SUMIF(Christophe!$A$3:$A$114,Planification!A22,Christophe!$C$3:$C$114) + SUMIF(Faton!$A$3:$A$112,Planification!A22,Faton!$C$3:$C$112) -> 0
B23: Milestone 6
A24: 14 | B24: Développer l'interface utilisateur de toutes les pages WEB | C24: 45292 | D24: =C24+H24 -> 45316 | E24: =C24+G24 -> 45306 | F24: 45330 | G24: 14 | H24: =F24-E24 -> 24 | I24: 8 | J24: Chris, Florian | K24: 20 | L24: 45 | M24: 29 | N24: =(K24+L24+4*M24) / 6 -> 30.166667 | O24: =SUMIF(Pamela!$A$3:$A$115,Planification!A24,Pamela!$C$3:$C$115) + SUMIF(Florian!$A$3:$A$110,Planification!A24,Florian!$C$3:$C$110) + SUMIF(Christophe!$A$3:$A$114,Planification!A24,Christophe!$C$3:$C$114) + SUMIF(Faton!$A$3:$A$112,Planification!A24,Faton!$C$3:$C$112) -> 15
A25: 15 | B25: Intégration de la logique back-end | C25: 45306 | D25: =C25+H25 -> 45341 | E25: =C25+G25 -> 45310 | F25: 45345 | G25: 4 | H25: =F25-E25 -> 35 | I25: 7, 12, 13, 14 | J25: Pamela, Faton | K25: 5 | L25: 10 | M25: 8 | N25: =(K25+L25+4*M25) / 6 -> 7.8333333 | O25: =SUMIF(Pamela!$A$3:$A$115,Planification!A25,Pamela!$C$3:$C$115) + SUMIF(Florian!$A$3:$A$110,Planification!A25,Florian!$C$3:$C$110) + SUMIF(Christophe!$A$3:$A$114,Planification!A25,Christophe!$C$3:$C$114) + SUMIF(Faton!$A$3:$A$112,Planification!A25,Faton!$C$3:$C$112) -> 0
B26: Milestone 7
A27: 16 | B27: Création de données fictives | C27: 45271 | D27: =C27+H27 -> 45306 | E27: =C27+G27 -> 45278 | F27: 45313 | G27: 7 | H27: =F27-E27 -> 35 | J27: Faton | K27: 2 | L27: 5 | M27: 3 | N27: =(K27+L27+4*M27) / 6 -> 3.1666667 | O27: =SUMIF(Pamela!$A$3:$A$115,Planification!A27,Pamela!$C$3:$C$115) + SUMIF(Florian!$A$3:$A$110,Planification!A27,Florian!$C$3:$C$110) + SUMIF(Christophe!$A$3:$A$114,Planification!A27,Christophe!$C$3:$C$114) + SUMIF(Faton!$A$3:$A$112,Planification!A27,Faton!$C$3:$C$112) -> 0
A28: 17 | B28: Développement du programme d'insertion de données | C28: 45292 | D28: =C28+H28 -> 45323 | E28: =C28+G28 -> 45306 | F28: 45337 | G28: 14 | H28: =F28-E28 -> 31 | I28: 16 | J28: Chris, Faton | K28: 4 | L28: 15 | M28: 10 | N28: =(K28+L28+4*M28) / 6 -> 9.8333333 | O28: =SUMIF(Pamela!$A$3:$A$115,Planification!A28,Pamela!$C$3:$C$115) + SUMIF(Florian!$A$3:$A$110,Planification!A28,Florian!$C$3:$C$110) + SUMIF(Christophe!$A$3:$A$114,Planification!A28,Christophe!$C$3:$C$114) + SUMIF(Faton!$A$3:$A$112,Planification!A28,Faton!$C$3:$C$112) -> 0
A29: 18 | B29: Test du programme d'insertion de données | C29: 45313 | D29: =C29+H29 -> 45338 | E29: =C29+G29 -> 45315 | F29: 45340 | G29: 2 | H29: =F29-E29 -> 25 | I29: 17 | J29: Chris, Florian | K29: 2 | L29: 8 | M29: 4 | N29: =(K29+L29+4*M29) / 6 -> 4.3333333 | O29: =SUMIF(Pamela!$A$3:$A$115,Planification!A29,Pamela!$C$3:$C$115) + SUMIF(Florian!$A$3:$A$110,Planification!A29,Florian!$C$3:$C$110) + SUMIF(Christophe!$A$3:$A$114,Planification!A29,Christophe!$C$3:$C$114) + SUMIF(Faton!$A$3:$A$112,Planification!A29,Faton!$C$3:$C$112) -> 0
B30: Milestone 8
A31: 19 | B31: Fonctionnalités admin : SuperGestion des intervenants | C31: 45313 | D31: =C31+H31 -> 45353 | E31: =C31+G31 -> 45328 | F31: 45368 | G31: 15 | H31: =F31-E31 -> 40 | I31: 14, 15 | J31: Chris | K31: 10 | L31: 25 | M31: 14 | N31: =(K31+L31+4*M31) / 6 -> 15.166667 | O31: =SUMIF(Pamela!$A$3:$A$115,Planification!A31,Pamela!$C$3:$C$115) + SUMIF(Florian!$A$3:$A$110,Planification!A31,Florian!$C$3:$C$110) + SUMIF(Christophe!$A$3:$A$114,Planification!A31,Christophe!$C$3:$C$114) + SUMIF(Faton!$A$3:$A$112,Planification!A31,Faton!$C$3:$C$112) -> 0
A32: 20 | B32: Fonctionnalités admin : Création des concours | C32: 45313 | D32: =C32+H32 -> 45346 | E32: =C32+G32 -> 45323 | F32: 45356 | G32: 10 | H32: =F32-E32 -> 33 | I32: 14, 15 | J32: Florian | K32: 8 | L32: 18 | M32: 16 | N32: =(K32+L32+4*M32) / 6 -> 15 | O32: =SUMIF(Pamela!$A$3:$A$115,Planification!A32,Pamela!$C$3:$C$115) + SUMIF(Florian!$A$3:$A$110,Planification!A32,Florian!$C$3:$C$110) + SUMIF(Christophe!$A$3:$A$114,Planification!A32,Christophe!$C$3:$C$114) + SUMIF(Faton!$A$3:$A$112,Planification!A32,Faton!$C$3:$C$112) -> 0
A33: 21 | B33: Fonctionnalités admin : Modification des concours | C33: 45318 | D33: =C33+H33 -> 45358 | E33: =C33+G33 -> 45328 | F33: 45368 | G33: 10 | H33: =F33-E33 -> 40 | I33: 20 | J33: Florian | K33: 8 | L33: 20 | M33: 15 | N33: =(K33+L33+4*M33) / 6 -> 14.666667 | O33: =SUMIF(Pamela!$A$3:$A$115,Planification!A33,Pamela!$C$3:$C$115) + SUMIF(Florian!$A$3:$A$110,Planification!A33,Florian!$C$3:$C$110) + SUMIF(Christophe!$A$3:$A$114,Planification!A33,Christophe!$C$3:$C$114) + SUMIF(Faton!$A$3:$A$112,Planification!A33,Faton!$C$3:$C$112) -> 0
A34: 22 | B34: Fonctionnalités admin : Gestion des comptes utilisateurs | C34: 45313 | D34: =C34+H34 -> 45353 | E34: =C34+G34 -> 45328 | F34: 45368 | G34: 15 | H34: =F34-E34 -> 40 | I34: 14, 15 | J34: Pamela | K34: 14 | L34: 30 | M34: 19 | N34: =(K34+L34+4*M34) / 6 -> 20 | O34: =SUMIF(Pamela!$A$3:$A$115,Planification!A34,Pamela!$C$3:$C$115) + SUMIF(Florian!$A$3:$A$110,Planification!A34,Florian!$C$3:$C$110) + SUMIF(Christophe!$A$3:$A$114,Planification!A34,Christophe!$C$3:$C$114) + SUMIF(Faton!$A$3:$A$112,Planification!A34,Faton!$C$3:$C$112) -> 0
A35: 23 | B35: Fonctionnalités coach classique : Création des gymnastes | C35: 45313 | D35: =C35+H35 -> 45346 | E35: =C35+G35 -> 45323 | F35: 45356 | G35: 10 | H35: =F35-E35 -> 33 | I35: 14.15 | J35: Faton | K35: 12 | L35: 24 | M35: 14 | N35: =(K35+L35+4*M35) / 6 -> 15.333333 | O35: =SUMIF(Pamela!$A$3:$A$115,Planification!A35,Pamela!$C$3:$C$115) + SUMIF(Florian!$A$3:$A$110,Planification!A35,Florian!$C$3:$C$110) + SUMIF(Christophe!$A$3:$A$114,Planification!A35,Christophe!$C$3:$C$114) + SUMIF(Faton!$A$3:$A$112,Planification!A35,Faton!$C$3:$C$112) -> 0
A36: 24 | B36: Fonctionnalités coach classique : Consulter infos gymnastes | C36: 45318 | D36: =C36+H36 -> 45363 | E36: =C36+G36 -> 45323 | F36: 45368 | G36: 5 | H36: =F36-E36 -> 45 | I36: 23 | J36: Chris | K36: 4 | L36: 11 | M36: 8 | N36: =(K36+L36+4*M36) / 6 -> 7.8333333 | O36: =SUMIF(Pamela!$A$3:$A$115,Planification!A36,Pamela!$C$3:$C$115) + SUMIF(Florian!$A$3:$A$110,Planification!A36,Florian!$C$3:$C$110) + SUMIF(Christophe!$A$3:$A$114,Planification!A36,Christophe!$C$3:$C$114) + SUMIF(Faton!$A$3:$A$112,Planification!A36,Faton!$C$3:$C$112) -> 0
A37: 25 | B37: Fonctionnalités coach classique : Modifier infos gymnastes | C37: 45318 | D37: =C37+H37 -> 45358 | E37: =C37+G37 -> 45328 | F37: 45368 | G37: 10 | H37: =F37-E37 -> 40 | I37: 23 | J37: Chris | K37: 8 | L37: 18 | M37: 16 | N37: =(K37+L37+4*M37) / 6 -> 15 | O37: =SUMIF(Pamela!$A$3:$A$115,Planification!A37,Pamela!$C$3:$C$115) + SUMIF(Florian!$A$3:$A$110,Planification!A37,Florian!$C$3:$C$110) + SUMIF(Christophe!$A$3:$A$114,Planification!A37,Christophe!$C$3:$C$114) + SUMIF(Faton!$A$3:$A$112,Planification!A37,Faton!$C$3:$C$112) -> 0
A38: 26 | B38: Fonctionnalités coach classique : Selection des gymnastes pour concourir | C38: 45318 | D38: =C38+H38 -> 45358 | E38: =C38+G38 -> 45328 | F38: 45368 | G38: 10 | H38: =F38-E38 -> 40 | I38: 20, 23 | J38: Florian | K38: 9 | L38: 20 | M38: 15 | N38: =(K38+L38+4*M38) / 6 -> 14.833333 | O38: =SUMIF(Pamela!$A$3:$A$115,Planification!A38,Pamela!$C$3:$C$115) + SUMIF(Florian!$A$3:$A$110,Planification!A38,Florian!$C$3:$C$110) + SUMIF(Christophe!$A$3:$A$114,Planification!A38,Christophe!$C$3:$C$114) + SUMIF(Faton!$A$3:$A$112,Planification!A38,Faton!$C$3:$C$112) -> 0
A39: 27 | B39: Fonctionnalités coach classique : Selection des catégories des gymnastes | C39: 45318 | D39: =C39+H39 -> 45364 | E39: =C39+G39 -> 45322 | F39: 45368 | G39: 4 | H39: =F39-E39 -> 46 | I39: 20, 23 | J39: Pamela | K39: 3 | L39: 9 | M39: 6 | N39: =(K39+L39+4*M39) / 6 -> 6 | O39: =SUMIF(Pamela!$A$3:$A$115,Planification!A39,Pamela!$C$3:$C$115) + SUMIF(Florian!$A$3:$A$110,Planification!A39,Florian!$C$3:$C$110) + SUMIF(Christophe!$A$3:$A$114,Planification!A39,Christophe!$C$3:$C$114) + SUMIF(Faton!$A$3:$A$112,Planification!A39,Faton!$C$3:$C$112) -> 0
A40: 28 | B40: Tester et valider les fonctionnalités du 1er prototype | C40: 45333 | D40: =C40+H40 -> 45363 | E40: =C40+G40 -> 45338 | F40: 45368 | G40: 5 | H40: =F40-E40 -> 30 | I40: 19, 20, 21, 22, 23, 24, 25, 26, 27 | J40: Equipe | K40: 2 | L40: 9 | M40: 5 | N40: =(K40+L40+4*M40) / 6 -> 5.1666667 | O40: =SUMIF(Pamela!$A$3:$A$115,Planification!A40,Pamela!$C$3:$C$115) + SUMIF(Florian!$A$3:$A$110,Planification!A40,Florian!$C$3:$C$110) + SUMIF(Christophe!$A$3:$A$114,Planification!A40,Christophe!$C$3:$C$114) + SUMIF(Faton!$A$3:$A$112,Planification!A40,Faton!$C$3:$C$112) -> 0
...

Sheet Pamela
A1: Pamela Verdon
A2: Numéro de la tâche | B2: Date | C2: Temps réel | D2: Description
A3: 0 | B3: 27.09.2023 - 18.10.2023 | C3: 20 | D3: Temps estimé des premières semaines (avant planification)
A4: 54 | B4: 45197 | C4: 1 | D4: Préparation RDV A0
A5: 53 | B5: 45198 | C5: 0.25 | D5: RDV acceptation A0
A6: 56 | B6: 45201 | C6: 0.25 | D6: Appel 1 avec mandant
A7: 54 | B7: 45218 | C7: 2 | D7: Préparation RDV A1
A8: 53 | B8: 45219 | C8: 0.25 | D8: RDV acceptation A1
A9: 50 | B9: 26.10.2023 - 01.11.2023 | C9: 4 | D9: Méthodologie : précision du choix développement itératif et incrémental, utilisation Trello Document de projet : corrections fonctionnalités, analyse de l'existant Gestion des risques : atténuation et prévention Références des documents
A10: 5 | B10: 45231 | C10: 3 | D10: PAQ (en appel équipe)
A11: 56 | B11: 45236 | C11: 0.25 | D11: Appel 2 avec mandant
A12: 2 | B12: 45236 | C12: 0.25 | D12: Questions posées au mandant pendant appel
A13: 51 | B13: 45236 | C13: 0.5 | D13: Corrections de la première lecture du document de projet par le mandant
A14: 6 | B14: 45238 | C14: 2 | D14: Plan de communication (en appel équipe)
A15: 54 | B15: 45239 | C15: 2 | D15: Préparation RDV A2
A16: 53 | B16: 45240 | C16: 0.25 | D16: RDV acceptation A2
A17: 52 | B17: 45241 | C17: 2 | D17: Modification nom de certaines fonctionnalités et donc changement dans planif et milestones
A18: 50 | B18: 45244 | C18: 2.25 | D18: Scénarios pour réaliser ensuite les diagrammes organisationnels BPMN
A19: 50 | B19: 45250 | C19: 1.25 | D19: Précision cahier des charges, plan de comm et avis utilisateurs finaux et esquisse de l'analyse multicritères pour choix de méthodologie
A20: 50 | B20: 45251 | C20: 2.5 | D20: Analyse multicritères pour choix méthodologie
A21: 50 | B21: 45252 | C21: 1.75 | D21: Gestion des risques (pas tout en vert)
... A26: 53 | B26: 45258 | C26: 0.25 | D26: RDV PDC1
A27: 10 | B27: 45266 | C27: 1
A28: N°56 | B28: 45271 | C28: 0.5 | D28: RDV Mandant
A29: 10 | B29: 45292 | C29: 1
A30: 9 | B30: 45294 | C30: 2 | D30: Recherches services cloud
A31: 9 | B31: 45296 | C31: 5 | D31: Recherches et rédaction
A32: 8 | B32: 45297 | C32: 2.5 | D32: Recherches et rédaction

Sheet Florian
A1: Florian Naef
A2: Numéro de la tâche | B2: Date | C2: Temps réel | D2: Description
A3: 0 | B3: 27.09.2023 - 18.10.2023 | C3: 20 | D3: Temps estimé des premières semaines (avant planification)
A4: 54 | B4: 45197 | C4: 1 | D4: Préparation RDV A0
A5: 53 | B5: 45198 | C5: 0.25 | D5: RDV acceptation A0
A6: 56 | B6: 45201 | C6: 0.25 | D6: Appel 1 avec mandant
A7: 54 | B7: 45218 | C7: 1 | D7: Préparation RDV A1
A8: 53 | B8: 45219 | C8: 0.25 | D8: RDV acceptation A1
A9: 50 | B9: 26.10.2023 - 01.11.2023 | C9: 1.25 | D9: Planification : explication des colonnes Trello Gestion des risques : atténuation et prévention Document de projet : concurrence
A10: 5 | B10: 45231 | C10: 3 | D10: PAQ (en appel équipe)
A11: 56 | B11: 45236 | C11: 0.25 | D11: Appel 2 avec mandant
A12: 2 | B12: 45236 | C12: 0.25 | D12: Questions posées au mandant pendant appel
A13: 6 | B13: 45238 | C13: 4 | D13: Plan de communication (en appel équipe)
A14: 54 | B14: 45239 | C14: 1.75 | D14: Préparation RDV A2
A15: 53 | B15: 45240 | C15: 0.25 | D15: RDV acceptation A2
A16: 3 | B16: 13.11.2023 - 26.11.2023 | C16: 12 | D16: Maquettes
A17: 53 | B17: 45258 | C17: 0.25 | D17: RDV PDC1
A18: N°56 | B18: 45271 | C18: 0.5 | D18: RDV Mandant
A19: 14 | C19: 2 | D19: Test code carte violette

Sheet Christophe
A1: Christophe Alexakis
A2: Numéro de la tâche | B2: Date | C2: Temps réel | D2: Description
A3: 0 | B3: 27.09.2023 - 18.10.2023 | C3: 20 | D3: Temps estimé des premières semaines (avant planification)
A4: 54 | B4: 45197 | C4: 0.5 | D4: Préparation RDV A0
A5: 53 | B5: 45198 | C5: 0.25 | D5: RDV acceptation A0
A6: 55 | B6: 45199 | C6: 0.2 | D6: PV A0
A7: 56 | B7: 45201 | C7: 0.25 | D7: Appel 1 avec mandant
A8: 54 | B8: 45218 | D8: Préparation RDV A1
A9: 53 | B9: 45219 | C9: 0.25 | D9: RDV acceptation A1
A10: 50 | B10: 26.10.2023 - 01.11.2023 | C10: 2.5 | D10: Gantt : recherches et essais Document de projet : temps des milestones Planification : estimation prix projet
A11: 1 | C11: 0.5 | D11: Couleurs dans les diagrammes, nommage des relations et corrections des 3 diagrammes (classes, MCD, MLD)
A12: 5 | B12: 45231 | C12: 3 | D12: PAQ (en appel équipe)
A13: 56 | B13: 45236 | C13: 0.25 | D13: Appel 2 avec mandant
A14: 2 | B14: 45236 | C14: 0.25 | D14: Questions posées au mandant pendant appel
A15: 6 | B15: 45238 | C15: 4 | D15: Plan de communication (en appel équipe)
A16: 54 | B16: 45239 | C16: 1 | D16: Préparation RDV A2
A17: 53 | B17: 45240 | C17: 0.25 | D17: RDV acceptation A2
A18: 50 | B18: 45241 | C18: 1.5 | D18: Estimer le temps des tâches et mettre en forme
A19: 3 | B19: 45252 | C19: 2 | D19: Conception
A20: 3 | B20: 45256 | C20: 7 | D20: Mettre au propre
A21: 53 | B21: 45258 | C21: 0.25 | D21: RDV PDC1
A22: 3 | B22: 45264 | C22: 3 | D22: Faire les dernières maquettes discutées
A23: N°56 | B23: 45271 | C23: 0.5 | D23: RDV Mandant
A24: 14 | B24: 45298 | C24: 5 | D24: Faire le modèle/exemple d'une page utilisateur (historique)
A25: 38 | B25: 45298 | C25: 0.1 | D25: On tient un truc, on lâche rien
A26: 14 | B26: 45347 | C26: 8 | D26: Formulaire d'inscirption des gymnastes, coach, admin, société

Sheet Faton
A1: Faton Zumeri
A2: Numéro de la tâche | B2: Date | C2: Temps réel | D2: Description
A3: 0 | B3: 27.09.2023 - 18.10.2023 | C3: 20 | D3: Temps estimé des premières semaines (avant planification)
A4: 54 | B4: 45197 | C4: 1 | D4: Préparation RDV A0
A5: 53 | B5: 45198 | C5: 0.25 | D5: RDV acceptation A0
A6: 56 | B6: 45201 | C6: 0.25 | D6: Appel 1 avec mandant
A7: 54 | B7: 45218 | C7: 1 | D7: Préparation RDV A1
A8: 53 | B8: 45219 | C8: 0.25 | D8: RDV acceptation A1
A9: 55 | B9: 45220 | C9: 0.75 | D9: PV A1
A10: 50 | B10: 45225 | C10: 1.5 | D10: Document de projet : fonctionnalités détaillées
A11: 6 | B11: 45234 | C11: 2 | D11: Premier jet du plan de communication
A12: 56 | B12: 45236 | C12: 0.25 | D12: Appel 2 avec mandant
A13: 2 | B13: 45236 | C13: 0.25 | D13: Questions posées au mandant pendant appel
A14: 6 | B14: 45238 | C14: 2 | D14: Plan de communication (en appel équipe)
A15: 54 | B15: 45239 | C15: 1 | D15: Préparation RDV A2
... A18: 53 | B18: 45258 | C18: 0.25 | D18: RDV PDC1
A19: N°56 | B19: 45271 | C19: 0.5 | D19: RDV Mandant
A20: N°57 | B20: 45273 | C20: 0.75 | D20: PV Mandant
A21: 52 | B21: 45297 | C21: 1 | D21: Modification fichier Import_v2
A22: 52 | B22: 45298 | C22: 1 | D22: Modification fichier Export_v2
